Traceback (most recent call last):
  File "/github/home/.cache/pypoetry/virtualenvs/viam-vvGuc1L8-py3.9/lib/python3.9/site-packages/jupyter_cache/executors/utils.py", line 58, in single_nb_execution
    executenb(
  File "/github/home/.cache/pypoetry/virtualenvs/viam-vvGuc1L8-py3.9/lib/python3.9/site-packages/nbclient/client.py", line 1204, in execute
    return NotebookClient(nb=nb, resources=resources, km=km, **kwargs).execute()
  File "/github/home/.cache/pypoetry/virtualenvs/viam-vvGuc1L8-py3.9/lib/python3.9/site-packages/nbclient/util.py", line 84, in wrapped
    return just_run(coro(*args, **kwargs))
  File "/github/home/.cache/pypoetry/virtualenvs/viam-vvGuc1L8-py3.9/lib/python3.9/site-packages/nbclient/util.py", line 62, in just_run
    return loop.run_until_complete(coro)
  File "/usr/lib/python3.9/asyncio/base_events.py", line 642, in run_until_complete
    return future.result()
  File "/github/home/.cache/pypoetry/virtualenvs/viam-vvGuc1L8-py3.9/lib/python3.9/site-packages/nbclient/client.py", line 663, in async_execute
    await self.async_execute_cell(
  File "/github/home/.cache/pypoetry/virtualenvs/viam-vvGuc1L8-py3.9/lib/python3.9/site-packages/nbclient/client.py", line 965, in async_execute_cell
    await self._check_raise_for_error(cell, cell_index, exec_reply)
  File "/github/home/.cache/pypoetry/virtualenvs/viam-vvGuc1L8-py3.9/lib/python3.9/site-packages/nbclient/client.py", line 862, in _check_raise_for_error
    raise CellExecutionError.from_cell_and_msg(cell, exec_reply_content)
nbclient.exceptions.CellExecutionError: An error occurred while executing the following cell:
------------------
# python-server.py
import asyncio
from viam.rpc.server import Server

async def main():
    srv = Server([MyCoolArm('my-arm')])

if __name__ == '__main__':
    asyncio.run(main())
------------------

[0;31m---------------------------------------------------------------------------[0m
[0;31mRuntimeError[0m                              Traceback (most recent call last)
Input [0;32mIn [8][0m, in [0;36m<cell line: 8>[0;34m()[0m
[1;32m      6[0m     srv [38;5;241m=[39m Server([MyCoolArm([38;5;124m'[39m[38;5;124mmy-arm[39m[38;5;124m'[39m)])
[1;32m      8[0m [38;5;28;01mif[39;00m [38;5;18m__name__[39m [38;5;241m==[39m [38;5;124m'[39m[38;5;124m__main__[39m[38;5;124m'[39m:
[0;32m----> 9[0m     [43masyncio[49m[38;5;241;43m.[39;49m[43mrun[49m[43m([49m[43mmain[49m[43m([49m[43m)[49m[43m)[49m

File [0;32m/usr/lib/python3.9/asyncio/runners.py:33[0m, in [0;36mrun[0;34m(main, debug)[0m
[1;32m      9[0m [38;5;124;03m"""Execute the coroutine and return the result.[39;00m
[1;32m     10[0m 
[1;32m     11[0m [38;5;124;03mThis function runs the passed coroutine, taking care of[39;00m
[0;32m   (...)[0m
[1;32m     30[0m [38;5;124;03m    asyncio.run(main())[39;00m
[1;32m     31[0m [38;5;124;03m"""[39;00m
[1;32m     32[0m [38;5;28;01mif[39;00m events[38;5;241m.[39m_get_running_loop() [38;5;129;01mis[39;00m [38;5;129;01mnot[39;00m [38;5;28;01mNone[39;00m:
[0;32m---> 33[0m     [38;5;28;01mraise[39;00m [38;5;167;01mRuntimeError[39;00m(
[1;32m     34[0m         [38;5;124m"[39m[38;5;124masyncio.run() cannot be called from a running event loop[39m[38;5;124m"[39m)
[1;32m     36[0m [38;5;28;01mif[39;00m [38;5;129;01mnot[39;00m coroutines[38;5;241m.[39miscoroutine(main):
[1;32m     37[0m     [38;5;28;01mraise[39;00m [38;5;167;01mValueError[39;00m([38;5;124m"[39m[38;5;124ma coroutine was expected, got [39m[38;5;132;01m{!r}[39;00m[38;5;124m"[39m[38;5;241m.[39mformat(main))

[0;31mRuntimeError[0m: asyncio.run() cannot be called from a running event loop
RuntimeError: asyncio.run() cannot be called from a running event loop

